Workbook

Sheet Inicio
A1: ASTROS · Banco de preguntas
A3: Cómo se usa | B3: Filtra la hoja Preguntas por universidad, área, tema o dificultad (flechas del encabezado). La hoja Resumen cuenta cuántas preguntas tienes de cada tipo.
A4: Agregar preguntas | B4: La fuente es preguntas.csv. Agrega filas ahí (o pídeselas a Claude) y corre herramientas/validar_banco.py: revisa errores, respalda y regenera este Excel.
A5: Simulacros | B5: herramientas/generar_simulacro.py arma un PDF listo para enviar al alumno, con hoja de claves y solucionario aparte.
A6: Resultados | B6: Registra los puntajes de cada simulacro en la hoja Avance del SIG.
A7: Formato del examen | B7: Las áreas por universidad están en la hoja Estructura. Confirma siempre con la guía oficial del postulante: los formatos cambian.

Sheet Preguntas
A1: id | B1: universidad | C1: examen | D1: area | E1: curso | F1: tema | G1: dificultad | H1: texto | I1: enunciado | J1: A | K1: B | L1: C | M1: D | N1: E | O1: respuesta | P1: solucion | Q1: tiempo_seg | R1: fuente | S1: estado
A2: PUCP-001 | B2: PUCP | C2: Primera Opción / Evaluación del Talento | D2: Razonamiento Matemático | E2: Razonamiento Matemático | F2: Sucesiones | G2: 1 | I2: Halla el término que sigue: 3; 7; 15; 31; ... | J2: 63 | K2: 64 | L2: 65 | M2: 72 | N2: 127 | O2: A | P2: Cada término es el anterior por 2 más 1: 31 × 2 + 1 = 63. | Q2: 90 | R2: Original ASTROS (estilo PUCP) | S2: Revisado por Claude
A3: PUCP-002 | B3: PUCP | C3: Primera Opción / Evaluación del Talento | D3: Razonamiento Matemático | E3: Razonamiento Matemático | F3: Sucesiones | G3: 2 | I3: Halla el término que sigue: 2; 5; 10; 17; 26; ... | J3: 26 | K3: 31 | L3: 35 | M3: 36 | N3: 37 | O3: E | P3: Los términos son n² + 1 para n = 1, 2, 3...; el sexto es 6² + 1 = 37. | Q3: 90 | R3: Original ASTROS (estilo PUCP) | S3: Revisado por Claude
A4: PUCP-003 | B4: PUCP | C4: Primera Opción / Evaluación del Talento | D4: Razonamiento Matemático | E4: Razonamiento Matemático | F4: Magnitudes proporcionales | G4: 1 | I4: Tres obreros hacen una obra en 12 días. Trabajando al mismo ritmo, ¿en cuántos días harían la misma obra 6 obreros? | J4: 3 | K4: 4 | L4: 6 | M4: 8 | N4: 24 | O4: C | P4: Obreros y días son inversamente proporcionales: 3 × 12 = 6 × d, entonces d = 6. | Q4: 90 | R4: Original ASTROS (estilo PUCP) | S4: Revisado por Claude
A5: PUCP-004 | B5: PUCP | C5: Primera Opción / Evaluación del Talento | D5: Razonamiento Matemático | E5: Razonamiento Matemático | F5: Porcentajes | G5: 2 | I5: El precio de un producto sube 20 % y luego baja 20 %. Respecto del precio inicial, el precio final: | J5: no varía | K5: aumenta 4 % | L5: disminuye 4 % | M5: disminuye 2 % | N5: aumenta 2 % | O5: C | P5: 1,20 × 0,80 = 0,96: el precio final es 96 % del inicial, es decir, disminuye 4 %. | Q5: 90 | R5: Original ASTROS (estilo PUCP) | S5: Revisado por Claude
A6: PUCP-005 | B6: PUCP | C6: Primera Opción / Evaluación del Talento | D6: Razonamiento Matemático | E6: Razonamiento Matemático | F6: Edades | G6: 2 | I6: Hace 5 años, la edad de Ana era el doble de la de Beto. Dentro de 5 años, sus edades sumarán 50 años. ¿Qué edad tiene Ana hoy? | J6: 20 | K6: 22 | L6: 25 | M6: 28 | N6: 30 | O6: C | P6: A − 5 = 2(B − 5) da A = 2B − 5. Además A + B + 10 = 50, así que A + B = 40. Entonces 3B − 5 = 40, B = 15 y A = 25. | Q6: 90 | R6: Original ASTROS (estilo PUCP) | S6: Revisado por Claude
A7: PUCP-006 | B7: PUCP | C7: Primera Opción / Evaluación del Talento | D7: Razonamiento Matemático | E7: Razonamiento Matemático | F7: Fracciones (trabajo) | G7: 2 | I7: El caño A llena un tanque en 6 horas y el caño B lo llena en 3 horas. Si se abren ambos a la vez con el tanque vacío, ¿en cuántas horas se llena? | J7: 1,5 | K7: 2 | L7: 2,5 | M7: 3 | N7: 4,5 | O7: B | P7: En una hora llenan 1/6 + 1/3 = 1/2 del tanque; el tanque completo se llena en 2 horas. | Q7: 90 | R7: Original ASTROS (estilo PUCP) | S7: Revisado por Claude
A8: PUCP-007 | B8: PUCP | C8: Primera Opción / Evaluación del Talento | D8: Razonamiento Matemático | E8: Razonamiento Matemático | F8: Probabilidades | G8: 2 | I8: Se lanzan dos dados comunes. ¿Cuál es la probabilidad de que la suma de los resultados sea 7? | J8: 1/12 | K8: 1/9 | L8: 1/6 | M8: 7/36 | N8: 1/3 | O8: C | P8: Hay 36 resultados posibles y 6 suman 7: (1,6), (2,5), (3,4), (4,3), (5,2), (6,1). Probabilidad 6/36 = 1/6. | Q8: 90 | R8: Original ASTROS (estilo PUCP) | S8: Revisado por Claude
A9: PUCP-008 | B9: PUCP | C9: Primera Opción / Evaluación del Talento | D9: Razonamiento Matemático | E9: Razonamiento Matemático | F9: Análisis combinatorio | G9: 1 | I9: ¿De cuántas maneras distintas se pueden ordenar todas las letras de la palabra ASTRO? | J9: 24 | K9: 60 | L9: 100 | M9: 110 | N9: 120 | O9: E | P9: Son 5 letras distintas: 5! = 120. | Q9: 90 | R9: Original ASTROS (estilo PUCP) | S9: Revisado por Claude
A10: PUCP-009 | B10: PUCP | C10: Primera Opción / Evaluación del Talento | D10: Razonamiento Matemático | E10: Razonamiento Matemático | F10: Promedios | G10: 2 | I10: El promedio de cinco números es 18. Si se retira uno de ellos, el promedio de los cuatro restantes es 17. ¿Qué número se retiró? | J10: 22 | K10: 24 | L10: 26 | M10: 34 | N10: 68 | O10: A | P10: Suma de los cinco: 5 × 18 = 90. Suma de los cuatro: 4 × 17 = 68. Número retirado: 90 − 68 = 22. | Q10: 90 | R10: Original ASTROS (estilo PUCP) | S10: Revisado por Claude
A11: PUCP-010 | B11: PUCP | C11: Primera Opción / Evaluación del Talento | D11: Razonamiento Matemático | E11: Razonamiento Matemático | F11: Operadores | G11: 2 | I11: Se define a ✱ b = 2a − b. Calcula (3 ✱ 1) ✱ 4. | J11: 2 | K11: 4 | L11: 5 | M11: 6 | N11: 8 | O11: D | P11: 3 ✱ 1 = 6 − 1 = 5. Luego 5 ✱ 4 = 10 − 4 = 6. | Q11: 90 | R11: Original ASTROS (estilo PUCP) | S11: Revisado por Claude
A12: PUCP-011 | B12: PUCP | C12: Primera Opción / Evaluación del Talento | D12: Razonamiento Matemático | E12: Razonamiento Matemático | F12: Conjuntos | G12: 2 | I12: En un aula de 40 alumnos, 25 estudian Matemática, 20 estudian Física y 8 no estudian ninguno de esos cursos. ¿Cuántos estudian ambos cursos? | J12: 5 | K12: 8 | L12: 10 | M12: 12 | N12: 13 | O12: E | P12: Estudian al menos uno: 40 − 8 = 32. Ambos: 25 + 20 − 32 = 13. | Q12: 90 | R12: Original ASTROS (estilo PUCP) | S12: Revisado por Claude
A13: PUCP-012 | B13: PUCP | C13: Primera Opción / Evaluación del Talento | D13: Razonamiento Matemático | E13: Razonamiento Matemático | F13: Móviles | G13: 1 | I13: Un auto recorre 180 km en 2 horas y 30 minutos. ¿Cuál es su velocidad media? | J13: 60 km/h | K13: 72 km/h | L13: 75 km/h | M13: 80 km/h | N13: 90 km/h | O13: B | P13: 2 h 30 min = 2,5 h. Velocidad = 180 ÷ 2,5 = 72 km/h. | Q13: 90 | R13: Original ASTROS (estilo PUCP) | S13: Revisado por Claude
... A22: PUCP-021 | B22: PUCP | C22: Primera Opción / Evaluación del Talento | D22: Matemática Básica | E22: Geometría | F22: Teorema de Pitágoras | G22: 1 | I22: Los catetos de un triángulo rectángulo miden 6 cm y 8 cm. ¿Cuánto mide la hipotenusa? | J22: 9 cm | K22: 10 cm | L22: 12 cm | M22: 14 cm | N22: 48 cm | O22: B | P22: h² = 6² + 8² = 36 + 64 = 100, h = 10 cm. | Q22: 90 | R22: Original ASTROS (estilo PUCP) | S22: Revisado por Claude
A23: PUCP-022 | B23: PUCP | C23: Primera Opción / Evaluación del Talento | D23: Comprensión Lectora | E23: Comprensión Lectora | F23: Idea principal | G23: 1 | H23: Durante años se creyó que dormir era tiempo perdido para el estudiante que se prepara para un examen. Sin embargo, diversas investigaciones muestran que, mientras dormimos, el cerebro reorganiza lo aprendido durante el día: fortalece las conexiones útiles y descarta información irrelevante. Por ello, quien sacrifica horas de sueño para estudiar más suele recordar menos al día siguiente. Esto no significa que basta con dormir para aprender; el sueño consolida lo que se estudió con atención, pero no puede fijar lo que nunca se comprendió. La recomendación, entonces, no es estudiar menos, sino distribuir el estudio en varios días y proteger el descanso, especialmente la noche previa a la evaluación. | I23: ¿Cuál es la idea principal del texto? | J23: Dormir es más importante que estudiar antes de un examen. | K23: El sueño ayuda a consolidar lo aprendido, por lo que conviene distribuir el estudio y proteger el descanso. | L23: El cerebro descarta toda la información que se estudia de noche. | M23: Los estudiantes que duermen poco tienen más tiempo para aprender. | N23: Basta con dormir bien para aprender cualquier tema. | O23: B | P23: El texto explica que el sueño consolida lo aprendido y concluye recomendando distribuir el estudio y proteger el descanso. A y E exageran; C y D contradicen el texto. | Q23: 75 | R23: Original ASTROS (estilo PUCP) | S23: Revisado por Claude
A24: PUCP-023 | B24: PUCP | C24: Primera Opción / Evaluación del Talento | D24: Comprensión Lectora | E24: Comprensión Lectora | F24: Inferencia | G24: 2 | H24: Durante años se creyó que dormir era tiempo perdido para el estudiante que se prepara para un examen. Sin embargo, diversas investigaciones muestran que, mientras dormimos, el cerebro reorganiza lo aprendido durante el día: fortalece las conexiones útiles y descarta información irrelevante. Por ello, quien sacrifica horas de sueño para estudiar más suele recordar menos al día siguiente. Esto no significa que basta con dormir para aprender; el sueño consolida lo que se estudió con atención, pero no puede fijar lo que nunca se comprendió. La recomendación, entonces, no es estudiar menos, sino distribuir el estudio en varios días y proteger el descanso, especialmente la noche previa a la evaluación. | I24: Del texto se infiere que un estudiante que no entendió un tema: | J24: lo recordará si duerme ocho horas. | K24: debe dejar de dormir para repasarlo. | L24: tiene que estudiarlo únicamente la noche anterior al examen. | M24: olvidará también los temas que sí comprendió. | N24: no lo fijará solo durmiendo; primero necesita comprenderlo. | O24: E | P24: El texto dice que el sueño 'no puede fijar lo que nunca se comprendió'. | Q24: 75 | R24: Original ASTROS (estilo PUCP) | S24: Revisado por Claude
A25: PUCP-024 | B25: PUCP | C25: Primera Opción / Evaluación del Talento | D25: Comprensión Lectora | E25: Comprensión Lectora | F25: Incompatibilidad | G25: 2 | H25: Durante años se creyó que dormir era tiempo perdido para el estudiante que se prepara para un examen. Sin embargo, diversas investigaciones muestran que, mientras dormimos, el cerebro reorganiza lo aprendido durante el día: fortalece las conexiones útiles y descarta información irrelevante. Por ello, quien sacrifica horas de sueño para estudiar más suele recordar menos al día siguiente. Esto no significa que basta con dormir para aprender; el sueño consolida lo que se estudió con atención, pero no puede fijar lo que nunca se comprendió. La recomendación, entonces, no es estudiar menos, sino distribuir el estudio en varios días y proteger el descanso, especialmente la noche previa a la evaluación. | I25: Es incompatible con lo que sostiene el autor afirmar que: | J25: el sueño reorganiza lo aprendido durante el día. | K25: conviene estudiar en varios días. | L25: trasnochar estudiando garantiza un mejor rendimiento al día siguiente. | M25: el descanso es importante la noche previa a la evaluación. | N25: el cerebro descarta información irrelevante mientras dormimos. | O25: C | P25: El autor afirma que quien sacrifica horas de sueño 'suele recordar menos al día siguiente'. | Q25: 75 | R25: Original ASTROS (estilo PUCP) | S25: Revisado por Claude
A26: PUCP-025 | B26: PUCP | C26: Primera Opción / Evaluación del Talento | D26: Comprensión Lectora | E26: Comprensión Lectora | F26: Tema central | G26: 1 | H26: Muchas personas piensan que reciclar es la solución principal al problema de los residuos. No obstante, el reciclaje es solo la última de varias estrategias. Antes de reciclar, conviene reducir lo que consumimos y reutilizar lo que ya tenemos, pues todo proceso de reciclaje requiere energía, transporte y agua. Una botella que se reutiliza diez veces evita fabricar nueve botellas nuevas; una botella reciclada, en cambio, debe ser recolectada, limpiada, triturada y fundida. Por eso, los especialistas sostienen que una ciudad que recicla mucho pero consume sin control no es necesariamente una ciudad sostenible. | I26: ¿Cuál es el tema central del texto? | J26: La historia del reciclaje de botellas. | K26: El reciclaje como una estrategia más, posterior a reducir y reutilizar. | L26: El consumo de agua en las ciudades. | M26: Las ventajas de fabricar botellas nuevas. | N26: La prohibición de reciclar en las ciudades. | O26: B | P26: El texto sostiene que el reciclaje es 'solo la última de varias estrategias', después de reducir y reutilizar. | Q26: 75 | R26: Original ASTROS (estilo PUCP) | S26: Revisado por Claude
A27: PUCP-026 | B27: PUCP | C27: Primera Opción / Evaluación del Talento | D27: Comprensión Lectora | E27: Comprensión Lectora | F27: Sentido contextual | G27: 2 | H27: Muchas personas piensan que reciclar es la solución principal al problema de los residuos. No obstante, el reciclaje es solo la última de varias estrategias. Antes de reciclar, conviene reducir lo que consumimos y reutilizar lo que ya tenemos, pues todo proceso de reciclaje requiere energía, transporte y agua. Una botella que se reutiliza diez veces evita fabricar nueve botellas nuevas; una botella reciclada, en cambio, debe ser recolectada, limpiada, triturada y fundida. Por eso, los especialistas sostienen que una ciudad que recicla mucho pero consume sin control no es necesariamente una ciudad sostenible. | I27: En el texto, la palabra SOSTENIBLE se refiere a una ciudad que: | J27: puede mantenerse en el tiempo sin agotar sus recursos. | K27: tiene muchas plantas de reciclaje. | L27: fabrica sus propias botellas. | M27: consume más de lo que produce. | N27: transporta sus residuos a otras ciudades. | O27: A | P27: El texto opone 'sostenible' a 'consumir sin control': se refiere a no agotar recursos en el tiempo. | Q27: 75 | R27: Original ASTROS (estilo PUCP) | S27: Revisado por Claude
A28: PUCP-027 | B28: PUCP | C28: Primera Opción / Evaluación del Talento | D28: Comprensión Lectora | E28: Comprensión Lectora | F28: Inferencia | G28: 3 | H28: Muchas personas piensan que reciclar es la solución principal al problema de los residuos. No obstante, el reciclaje es solo la última de varias estrategias. Antes de reciclar, conviene reducir lo que consumimos y reutilizar lo que ya tenemos, pues todo proceso de reciclaje requiere energía, transporte y agua. Una botella que se reutiliza diez veces evita fabricar nueve botellas nuevas; una botella reciclada, en cambio, debe ser recolectada, limpiada, triturada y fundida. Por eso, los especialistas sostienen que una ciudad que recicla mucho pero consume sin control no es necesariamente una ciudad sostenible. | I28: Según el texto, reutilizar una botella es preferible a reciclarla porque: | J28: las botellas recicladas no sirven. | K28: reciclar no requiere energía. | L28: una botella reciclada dura diez veces más. | M28: reutilizar está prohibido en muchas ciudades. | N28: evita los costos de energía, transporte y agua que exige reciclar. | O28: E | P28: El texto indica que reciclar requiere energía, transporte y agua, mientras que reutilizar evita fabricar botellas nuevas. | Q28: 75 | R28: Original ASTROS (estilo PUCP) | S28: Revisado por Claude
A29: PUCP-028 | B29: PUCP | C29: Primera Opción / Evaluación del Talento | D29: Redacción | E29: Redacción | F29: Conectores | G29: 1 | I29: Elige el conector adecuado: «Estudió durante varios meses; ______, no alcanzó el puntaje mínimo.» | J29: por lo tanto | K29: sin embargo | L29: es decir | M29: además | N29: por ejemplo | O29: B | P29: Hay una relación de oposición entre estudiar mucho y no alcanzar el puntaje: 'sin embargo'. | Q29: 75 | R29: Original ASTROS (estilo PUCP) | S29: Revisado por Claude
A30: PUCP-029 | B30: PUCP | C30: Primera Opción / Evaluación del Talento | D30: Redacción | E30: Redacción | F30: Puntuación | G30: 2 | I30: ¿Qué oración está correctamente puntuada? | J30: María, estudia en la PUCP. | K30: Los alumnos, que llegaron tarde no rindieron el examen. | L30: Lima, la capital del Perú, tiene muchas universidades. | M30: Compré: lápices, cuadernos y reglas. | N30: Sin embargo los resultados, fueron buenos. | O30: C | P30: La aposición explicativa 'la capital del Perú' va entre comas. En A y E sobra la coma entre sujeto y verbo o está mal ubicada; en B falta cerrar el inciso; en D no van dos puntos tras el verbo. | Q30: 75 | R30: Original ASTROS (estilo PUCP) | S30: Revisado por Claude
A31: PUCP-030 | B31: PUCP | C31: Primera Opción / Evaluación del Talento | D31: Redacción | E31: Redacción | F31: Tildación | G31: 2 | I31: ¿En qué oración la tilde está bien empleada? | J31: Él no sabe donde queda la biblioteca. | K31: ¿Cuándo empieza el examen? | L31: Te lo dí ayer. | M31: El examen fué difícil. | N31: Quiero que me digas porqué no viniste. | O31: B | P31: 'Cuándo' interrogativo lleva tilde. 'Dónde' debía tildarse en A (interrogativa indirecta); 'di' y 'fue' son monosílabos sin tilde; en E corresponde 'por qué'. | Q31: 75 | R31: Original ASTROS (estilo PUCP) | S31: Revisado por Claude
A32: PUCP-031 | B32: PUCP | C32: Primera Opción / Evaluación del Talento | D32: Redacción | E32: Redacción | F32: Precisión léxica | G32: 1 | I32: Reemplaza el verbo subrayado por uno más preciso: «El ministro DIJO su renuncia ayer.» | J32: habló | K32: presentó | L32: hizo | M32: contó | N32: puso | O32: B | P32: Una renuncia se 'presenta'. Los demás verbos son imprecisos o incorrectos en este contexto. | Q32: 75 | R32: Original ASTROS (estilo PUCP) | S32: Revisado por Claude
A33: PUCP-032 | B33: PUCP | C33: Primera Opción / Evaluación del Talento | D33: Redacción | E33: Redacción | F33: Eliminación de oraciones | G33: 2 | I33: Señala la oración que debe eliminarse por no corresponder al tema: (I) El café es una de las bebidas más consumidas del mundo. (II) Su cultivo se concentra en zonas tropicales. (III) El Perú es uno de los principales exportadores de café orgánico. (IV) El té verde tiene antioxidantes. (V) La cosecha de café da trabajo a miles de familias. | J33: I | K33: II | L33: III | M33: IV | N33: V | O33: D | P33: Todas las oraciones tratan del café, excepto la IV, que habla del té verde. | Q33: 75 | R33: Original ASTROS (estilo PUCP) | S33: Revisado por Claude
A34: PUCP-033 | B34: PUCP | C34: Primera Opción / Evaluación del Talento | D34: Redacción | E34: Redacción | F34: Plan de redacción | G34: 3 | I34: Ordena las ideas: (1) Finalmente, revisa tus errores para no repetirlos. (2) Primero, identifica los temas que más te cuestan. (3) Luego, practica con preguntas de exámenes anteriores. (4) Cómo preparar un simulacro eficaz. (5) Después, toma un simulacro cronometrado. | J34: 4-2-3-5-1 | K34: 2-3-5-1-4 | L34: 4-3-2-5-1 | M34: 4-2-5-3-1 | N34: 2-4-3-1-5 | O34: A | P34: El título (4) va primero y luego la secuencia marcada por los conectores: primero (2), luego (3), después (5), finalmente (1). | Q34: 75 | R34: Original ASTROS (estilo PUCP) | S34: Revisado por Claude
A35: ULIMA-001 | B35: ULIMA | C35: Examen de Escolares / Egresados | D35: Razonamiento Matemático | E35: Razonamiento Matemático | F35: Sucesiones | G35: 1 | I35: Halla el término que sigue: 1; 1; 2; 3; 5; 8; ... | J35: 11 | K35: 12 | L35: 13 | M35: 14 | N35: 21 | O35: C | P35: Cada término es la suma de los dos anteriores: 5 + 8 = 13. | Q35: 90 | R35: Original ASTROS (estilo ULIMA) | S35: Revisado por Claude
A36: ULIMA-002 | B36: ULIMA | C36: Examen de Escolares / Egresados | D36: Razonamiento Matemático | E36: Razonamiento Matemático | F36: Sucesiones | G36: 2 | I36: Halla el término que sigue: 4; 9; 19; 39; ... | J36: 59 | K36: 69 | L36: 78 | M36: 79 | N36: 80 | O36: D | P36: Cada término es el anterior por 2 más 1: 39 × 2 + 1 = 79. | Q36: 90 | R36: Original ASTROS (estilo ULIMA) | S36: Revisado por Claude
A37: ULIMA-003 | B37: ULIMA | C37: Examen de Escolares / Egresados | D37: Razonamiento Matemático | E37: Razonamiento Matemático | F37: Edades | G37: 2 | I37: Un padre tiene 40 años y su hijo 10. ¿Dentro de cuántos años la edad del padre será el triple de la de su hijo? | J37: 5 | K37: 8 | L37: 10 | M37: 12 | N37: 15 | O37: A | P37: 40 + x = 3(10 + x), entonces 40 + x = 30 + 3x y x = 5. | Q37: 90 | R37: Original ASTROS (estilo ULIMA) | S37: Revisado por Claude
A38: ULIMA-004 | B38: ULIMA | C38: Examen de Escolares / Egresados | D38: Razonamiento Matemático | E38: Razonamiento Matemático | F38: Porcentajes | G38: 1 | I38: De 200 clientes de una tienda, el 60 % compra algo y, de ellos, el 25 % paga con Yape. ¿Cuántos clientes pagan con Yape? | J38: 25 | K38: 30 | L38: 40 | M38: 50 | N38: 60 | O38: B | P38: 60 % de 200 = 120; 25 % de 120 = 30. | Q38: 90 | R38: Original ASTROS (estilo ULIMA) | S38: Revisado por Claude
A39: ULIMA-005 | B39: ULIMA | C39: Examen de Escolares / Egresados | D39: Razonamiento Matemático | E39: Razonamiento Matemático | F39: Calendarios | G39: 2 | I39: Si hoy es lunes, ¿qué día de la semana será dentro de 100 días? | J39: martes | K39: miércoles | L39: jueves | M39: viernes | N39: sábado | O39: B | P39: 100 = 7 × 14 + 2: avanzan 2 días desde el lunes, es decir, miércoles. | Q39: 90 | R39: Original ASTROS (estilo ULIMA) | S39: Revisado por Claude
A40: ULIMA-006 | B40: ULIMA | C40: Examen de Escolares / Egresados | D40: Razonamiento Matemático | E40: Razonamiento Matemático | F40: Conteo | G40: 2 | I40: ¿Cuántos números de dos cifras tienen sus dos cifras pares? | J40: 16 | K40: 20 | L40: 25 | M40: 40 | N40: 45 | O40: B | P40: Decenas: 2, 4, 6 u 8 (4 opciones; no puede ser 0). Unidades: 0, 2, 4, 6 u 8 (5 opciones). Total 4 × 5 = 20. | Q40: 90 | R40: Original ASTROS (estilo ULIMA) | S40: Revisado por Claude
... A53: ULIMA-019 | B53: ULIMA | C53: Examen de Escolares / Egresados | D53: Razonamiento Verbal | E53: Razonamiento Verbal | F53: Término excluido | G53: 1 | I53: Señala el término que no pertenece al grupo: | J53: rojo | K53: azul | L53: verde | M53: redondo | N53: amarillo | O53: D | P53: Todos son colores excepto 'redondo', que es una forma. | Q53: 75 | R53: Original ASTROS (estilo ULIMA) | S53: Revisado por Claude
A54: ULIMA-020 | B54: ULIMA | C54: Examen de Escolares / Egresados | D54: Comprensión Lectora | E54: Comprensión Lectora | F54: Idea principal | G54: 1 | H54: La anchoveta es un pez pequeño, pero su importancia para el Perú es enorme. Gracias a la corriente de Humboldt, de aguas frías y ricas en nutrientes, el mar peruano alberga una de las mayores poblaciones de este pez en el mundo. La mayor parte de la captura se destina a producir harina y aceite de pescado, que se exportan para alimentar animales de granja y peces de criadero. Sin embargo, solo una pequeña fracción llega a la mesa de los peruanos, a pesar de que la anchoveta es barata y muy nutritiva. Diversas campañas han intentado cambiar esta situación, aunque los hábitos alimentarios cambian lentamente. | I54: ¿Cuál es la idea principal del texto? | J54: La corriente de Humboldt es fría y rica en nutrientes. | K54: Las campañas de consumo de anchoveta fueron un éxito. | L54: Los peruanos no comen pescado. | M54: La harina de pescado alimenta a los animales de granja. | N54: La anchoveta es muy importante para el Perú, pero se usa sobre todo para exportar harina y aceite y poco para el consumo humano. | O54: E | P54: El texto presenta la importancia de la anchoveta y el contraste entre su uso industrial y su poco consumo directo. | Q54: 75 | R54: Original ASTROS (estilo ULIMA) | S54: Revisado por Claude
A55: ULIMA-021 | B55: ULIMA | C55: Examen de Escolares / Egresados | D55: Comprensión Lectora | E55: Comprensión Lectora | F55: Inferencia | G55: 2 | H55: La anchoveta es un pez pequeño, pero su importancia para el Perú es enorme. Gracias a la corriente de Humboldt, de aguas frías y ricas en nutrientes, el mar peruano alberga una de las mayores poblaciones de este pez en el mundo. La mayor parte de la captura se destina a producir harina y aceite de pescado, que se exportan para alimentar animales de granja y peces de criadero. Sin embargo, solo una pequeña fracción llega a la mesa de los peruanos, a pesar de que la anchoveta es barata y muy nutritiva. Diversas campañas han intentado cambiar esta situación, aunque los hábitos alimentarios cambian lentamente. | I55: Se infiere del texto que, si la corriente de Humboldt se debilitara: | J55: probablemente disminuiría la población de anchoveta. | K55: aumentaría el consumo de anchoveta en el Perú. | L55: la anchoveta sería más cara que la carne. | M55: se dejaría de exportar harina de pescado de inmediato. | N55: las campañas de consumo tendrían éxito. | O55: A | P55: El texto atribuye la gran población de anchoveta a las aguas frías y nutritivas de esa corriente. | Q55: 75 | R55: Original ASTROS (estilo ULIMA) | S55: Revisado por Claude
A56: ULIMA-022 | B56: ULIMA | C56: Examen de Escolares / Egresados | D56: Comprensión Lectora | E56: Comprensión Lectora | F56: Sentido contextual | G56: 1 | H56: La anchoveta es un pez pequeño, pero su importancia para el Perú es enorme. Gracias a la corriente de Humboldt, de aguas frías y ricas en nutrientes, el mar peruano alberga una de las mayores poblaciones de este pez en el mundo. La mayor parte de la captura se destina a producir harina y aceite de pescado, que se exportan para alimentar animales de granja y peces de criadero. Sin embargo, solo una pequeña fracción llega a la mesa de los peruanos, a pesar de que la anchoveta es barata y muy nutritiva. Diversas campañas han intentado cambiar esta situación, aunque los hábitos alimentarios cambian lentamente. | I56: En el texto, la palabra FRACCIÓN significa: | J56: fragmento de roca | K56: número | L56: división | M56: parte | N56: quebrado | O56: D | P56: 'Una pequeña fracción llega a la mesa' quiere decir una pequeña parte de la captura. | Q56: 75 | R56: Original ASTROS (estilo ULIMA) | S56: Revisado por Claude
A57: UPC-001 | B57: UPC | C57: Evaluación Integral | D57: Razonamiento Matemático | E57: Razonamiento Matemático | F57: Sucesiones | G57: 2 | I57: Halla el término que sigue: 5; 10; 8; 16; 14; ... | J57: 12 | K57: 18 | L57: 24 | M57: 28 | N57: 30 | O57: D | P57: Se alterna ×2 y −2: 14 × 2 = 28. | Q57: 90 | R57: Original ASTROS (estilo UPC) | S57: Revisado por Claude
A58: UPC-002 | B58: UPC | C58: Evaluación Integral | D58: Razonamiento Matemático | E58: Razonamiento Matemático | F58: Proporcionalidad | G58: 1 | I58: Si 4 cuadernos cuestan S/ 18, ¿cuánto cuestan 10 cuadernos? | J58: S/ 36 | K58: S/ 40 | L58: S/ 45 | M58: S/ 48 | N58: S/ 54 | O58: C | P58: Cada cuaderno cuesta 18 ÷ 4 = 4,5; diez cuestan S/ 45. | Q58: 90 | R58: Original ASTROS (estilo UPC) | S58: Revisado por Claude
A59: UPC-003 | B59: UPC | C59: Evaluación Integral | D59: Razonamiento Matemático | E59: Razonamiento Matemático | F59: Descuentos | G59: 1 | I59: Un celular cuesta S/ 1 200 y tiene 15 % de descuento. ¿Cuál es el precio final? | J59: S/ 1 020 | K59: S/ 1 050 | L59: S/ 1 080 | M59: S/ 1 100 | N59: S/ 1 180 | O59: A | P59: 15 % de 1 200 = 180; 1 200 − 180 = S/ 1 020. | Q59: 90 | R59: Original ASTROS (estilo UPC) | S59: Revisado por Claude
A60: UPC-004 | B60: UPC | C60: Evaluación Integral | D60: Razonamiento Matemático | E60: Razonamiento Matemático | F60: Promedio ponderado | G60: 2 | I60: Un curso se califica así: práctica 30 %, parcial 30 % y final 40 %. Si un alumno saca 12, 15 y 18 respectivamente, ¿cuál es su nota? | J60: 14,5 | K60: 15 | L60: 15,3 | M60: 15,8 | N60: 16 | O60: C | P60: 0,3 × 12 + 0,3 × 15 + 0,4 × 18 = 3,6 + 4,5 + 7,2 = 15,3. | Q60: 90 | R60: Original ASTROS (estilo UPC) | S60: Revisado por Claude
...

Sheet Estructura
A1: Universidad | B1: Áreas a preparar (referencial) | C1: Confianza
A2: PUCP | B2: Razonamiento matemático, matemática básica, comprensión lectora, redacción | C2: Confirmar en la guía del postulante PUCP
A3: ULIMA | B3: Razonamiento matemático, razonamiento verbal, comprensión lectora | C3: Confirmar en ulima.edu.pe
A4: UPC | B4: Evaluación integral online: aptitud matemática y verbal | C4: Confirmar al inscribirse (610-5030)
A5: UPCH | B5: Matemática, razonamiento verbal, biología, química, física (énfasis ciencias de la salud) | C5: Confirmar en cayetano.edu.pe
A6: Universitario | B6: Prácticas y exámenes por curso (Cálculo, Física, Química, Estadística...) | C6: Según el sílabo del curso

Sheet Resumen
A1: Universidad | B1: Área | C1: Fácil (1) | D1: Media (2) | E1: Difícil (3) | F1: Total
A2: PUCP | B2: Comprensión Lectora | C2: =COUNTIFS(Preguntas!$B:$B,A2,Preguntas!$D:$D,B2,Preguntas!$G:$G,1) | D2: =COUNTIFS(Preguntas!$B:$B,A2,Preguntas!$D:$D,B2,Preguntas!$G:$G,2) | E2: =COUNTIFS(Preguntas!$B:$B,A2,Preguntas!$D:$D,B2,Preguntas!$G:$G,3) | F2: =SUM(C2:E2)
A3: PUCP | B3: Matemática Básica | C3: =COUNTIFS(Preguntas!$B:$B,A3,Preguntas!$D:$D,B3,Preguntas!$G:$G,1) | D3: =COUNTIFS(Preguntas!$B:$B,A3,Preguntas!$D:$D,B3,Preguntas!$G:$G,2) | E3: =COUNTIFS(Preguntas!$B:$B,A3,Preguntas!$D:$D,B3,Preguntas!$G:$G,3) | F3: =SUM(C3:E3)
A4: PUCP | B4: Razonamiento Matemático | C4: =COUNTIFS(Preguntas!$B:$B,A4,Preguntas!$D:$D,B4,Preguntas!$G:$G,1) | D4: =COUNTIFS(Preguntas!$B:$B,A4,Preguntas!$D:$D,B4,Preguntas!$G:$G,2) | E4: =COUNTIFS(Preguntas!$B:$B,A4,Preguntas!$D:$D,B4,Preguntas!$G:$G,3) | F4: =SUM(C4:E4)
A5: PUCP | B5: Redacción | C5: =COUNTIFS(Preguntas!$B:$B,A5,Preguntas!$D:$D,B5,Preguntas!$G:$G,1) | D5: =COUNTIFS(Preguntas!$B:$B,A5,Preguntas!$D:$D,B5,Preguntas!$G:$G,2) | E5: =COUNTIFS(Preguntas!$B:$B,A5,Preguntas!$D:$D,B5,Preguntas!$G:$G,3) | F5: =SUM(C5:E5)
A6: ULIMA | B6: Comprensión Lectora | C6: =COUNTIFS(Preguntas!$B:$B,A6,Preguntas!$D:$D,B6,Preguntas!$G:$G,1) | D6: =COUNTIFS(Preguntas!$B:$B,A6,Preguntas!$D:$D,B6,Preguntas!$G:$G,2) | E6: =COUNTIFS(Preguntas!$B:$B,A6,Preguntas!$D:$D,B6,Preguntas!$G:$G,3) | F6: =SUM(C6:E6)
A7: ULIMA | B7: Matemática | C7: =COUNTIFS(Preguntas!$B:$B,A7,Preguntas!$D:$D,B7,Preguntas!$G:$G,1) | D7: =COUNTIFS(Preguntas!$B:$B,A7,Preguntas!$D:$D,B7,Preguntas!$G:$G,2) | E7: =COUNTIFS(Preguntas!$B:$B,A7,Preguntas!$D:$D,B7,Preguntas!$G:$G,3) | F7: =SUM(C7:E7)
A8: ULIMA | B8: Razonamiento Matemático | C8: =COUNTIFS(Preguntas!$B:$B,A8,Preguntas!$D:$D,B8,Preguntas!$G:$G,1) | D8: =COUNTIFS(Preguntas!$B:$B,A8,Preguntas!$D:$D,B8,Preguntas!$G:$G,2) | E8: =COUNTIFS(Preguntas!$B:$B,A8,Preguntas!$D:$D,B8,Preguntas!$G:$G,3) | F8: =SUM(C8:E8)
A9: ULIMA | B9: Razonamiento Verbal | C9: =COUNTIFS(Preguntas!$B:$B,A9,Preguntas!$D:$D,B9,Preguntas!$G:$G,1) | D9: =COUNTIFS(Preguntas!$B:$B,A9,Preguntas!$D:$D,B9,Preguntas!$G:$G,2) | E9: =COUNTIFS(Preguntas!$B:$B,A9,Preguntas!$D:$D,B9,Preguntas!$G:$G,3) | F9: =SUM(C9:E9)
A10: UPC | B10: Comprensión Lectora | C10: =COUNTIFS(Preguntas!$B:$B,A10,Preguntas!$D:$D,B10,Preguntas!$G:$G,1) | D10: =COUNTIFS(Preguntas!$B:$B,A10,Preguntas!$D:$D,B10,Preguntas!$G:$G,2) | E10: =COUNTIFS(Preguntas!$B:$B,A10,Preguntas!$D:$D,B10,Preguntas!$G:$G,3) | F10: =SUM(C10:E10)
A11: UPC | B11: Matemática | C11: =COUNTIFS(Preguntas!$B:$B,A11,Preguntas!$D:$D,B11,Preguntas!$G:$G,1) | D11: =COUNTIFS(Preguntas!$B:$B,A11,Preguntas!$D:$D,B11,Preguntas!$G:$G,2) | E11: =COUNTIFS(Preguntas!$B:$B,A11,Preguntas!$D:$D,B11,Preguntas!$G:$G,3) | F11: =SUM(C11:E11)
A12: UPC | B12: Razonamiento Matemático | C12: =COUNTIFS(Preguntas!$B:$B,A12,Preguntas!$D:$D,B12,Preguntas!$G:$G,1) | D12: =COUNTIFS(Preguntas!$B:$B,A12,Preguntas!$D:$D,B12,Preguntas!$G:$G,2) | E12: =COUNTIFS(Preguntas!$B:$B,A12,Preguntas!$D:$D,B12,Preguntas!$G:$G,3) | F12: =SUM(C12:E12)
A13: UPC | B13: Razonamiento Verbal | C13: =COUNTIFS(Preguntas!$B:$B,A13,Preguntas!$D:$D,B13,Preguntas!$G:$G,1) | D13: =COUNTIFS(Preguntas!$B:$B,A13,Preguntas!$D:$D,B13,Preguntas!$G:$G,2) | E13: =COUNTIFS(Preguntas!$B:$B,A13,Preguntas!$D:$D,B13,Preguntas!$G:$G,3) | F13: =SUM(C13:E13)
... A19: UPCH | B19: Razonamiento Verbal | C19: =COUNTIFS(Preguntas!$B:$B,A19,Preguntas!$D:$D,B19,Preguntas!$G:$G,1) | D19: =COUNTIFS(Preguntas!$B:$B,A19,Preguntas!$D:$D,B19,Preguntas!$G:$G,2) | E19: =COUNTIFS(Preguntas!$B:$B,A19,Preguntas!$D:$D,B19,Preguntas!$G:$G,3) | F19: =SUM(C19:E19)
A20: TOTAL | C20: =SUM(C2:C19) | D20: =SUM(D2:D19) | E20: =SUM(E2:E19) | F20: =SUM(F2:F19)
